Workbook

Sheet IS
A1: In Millions of INR except Per Share | B1: FY 2023 | C1: FY 2024
A2: 12 Months Ending | B2: 03/31/2023 | C2: 03/31/2024
A3: Revenue | B3: 432788.7 | C3: 477584.5
A5: + Sales & Services Revenue | B5: 432788.7 | C5: 477584.5
A6: Gross Profit | B6: — | C6: —
A7: + Other Operating Income | B7: 6068.1 | C7: 7384
A8: - Operating Expenses | B8: 344470.2 | C8: 378009.5
A9: + Selling & Marketing | B9: 42921.8 | C9: 49677.9
A10: + Research & Development | B10: 22856.2 | C10: 30923.7
A11: + Depreciation & Amortization | B11: 25294.3 | C11: 25566.4
A12: + Prov For Doubtful Accts | B12: 426.2 | C12: 905.9
A13: + Other Operating Expense | B13: 252971.7 | C13: 270935.6
A14: Operating Income (Loss) | B14: 94386.6 | C14: 106959
A15: - Non-Operating (Income) Loss | B15: -1645.5 | C15: -10388.6
A16: + Interest Expense, Net | B16: 430.5 | C16: -624.8
A17: + Interest Expense | B17: 1720 | C17: 2384.7
A18: - Interest Income | B18: 1289.5 | C18: 3009.5
... A20: + Foreign Exch (Gain) Loss | B20: 1261 | C20: -361.3
A21: + (Income) Loss from Affiliates | B21: — | C21: —
A22: + Other Non-Op (Income) Loss | B22: -72.1 | C22: -4888.4
A23: Pretax Income (Loss), Adjusted | B23: 96032.1 | C23: 117347.6
A24: - Abnormal Losses (Gains) | B24: 1947.8 | C24: 6468.7
A25: + Disposal of Assets | B25: -75.4 | C25: 99.7
A26: + Asset Write-Down | B26: 302.5 | C26: 70.5
A27: + Impairment of Goodwill | B27: — | C27: —
A28: + Legal Settlement | B28: 2278 | C28: 5175.3
A29: + Restructuring | B29: -563.5 | C29: -232.1
A30: + Sale of Investments | B30: -1606.8 | C30: -3199.1
A31: + Unrealized Investments | B31: 1613 | C31: 4554.4
A32: Pretax Income (Loss), GAAP | B32: 94084.3 | C32: 110878.9
A33: - Income Tax Expense (Benefit) | B33: 8475.9 | C33: 14394.5
A34: + Current Income Tax | B34: 18692.2 | C34: 19893
A35: + Deferred Income Tax | B35: -10216.3 | C35: -5498.5
A36: - (Income) Loss from Affiliates | B36: 479 | C36: 384.1
A37: Income (Loss) from Cont Ops | B37: 85129.4 | C37: 96100.3
A38: - Net Extraordinary Losses (Gains) | B38: 0 | C38: 0
A39: + Discontinued Operations | B39: 0 | C39: 0
... A60: Diluted EPS from Cont Ops, Adjusted | B60: 35.8846 | C60: 41.7999
A62: Reference Items
A63: Accounting Standard | B63: IN GAAP | C63: IN GAAP
...

Sheet Revenue Projection
J2: Best Case
T3: best case
A4: Revenue | B4: In Rs Mn | C4: 2024 | D4: 2025* | E4: 2026* | F4: 2027* | G4: 2028* | H4: 2029* | I4: 2030* | J4: 2031* | K4: 2032* | L4: 2033* | M4: 2034* | P4: In Rs Mn | Q4: 2024 | R4: 2025* | S4: 2026* | T4: 2027* | U4: 2028* | V4: 2029* | W4: 2030* | X4: 2031* | Y4: 2032* | Z4: 2033* | AA4: 2034*
B5: U.S. Speciality | C5: 78564.897 | D5: =(1+R11)*C5 -> 98206.121 | E5: =(1+S11)*D5 -> 122757.65 | F5: =(1+T11)*E5 -> 153447.06 | G5: =(1+U11)*F5 -> 191808.83 | H5: =(1+V11)*G5 -> 239761.04 | I5: =(1+W11)*H5 -> 292700.28 | J5: =(1+X11)*I5 -> 348781.65 | K5: =(1+Y11)*J5 -> 405423.79 | ... M5: =(1+AA11)*L5 -> 507206.57 | P5: ANDA Growth | Q5: 0.019 | R5: =Q5+($AA$5-$Q$5)/10 -> 0.0211 | S5: =R5+($AA$5-$Q$5)/10 -> 0.0232 | T5: =S5+($AA$5-$Q$5)/10 -> 0.0253 | U5: =T5+($AA$5-$Q$5)/10 -> 0.0274 | V5: =U5+($AA$5-$Q$5)/10 -> 0.0295 | W5: =V5+($AA$5-$Q$5)/10 -> 0.0316 | X5: =W5+($AA$5-$Q$5)/10 -> 0.0337 | Y5: =X5+($AA$5-$Q$5)/10 -> 0.0358 | Z5: =Y5+($AA$5-$Q$5)/10 -> 0.0379 | AA5: 0.04
B6: U.S. Generics | C6: 76625.023 | D6: =(1+R7)*C6 -> 83327.529 | E6: =(1+S7)*D6 -> 90802.675 | F6: =(1+T7)*E6 -> 99151.481 | G6: =(1+U7)*F6 -> 108489.67 | H6: =(1+V7)*G6 -> 118949.97 | I6: =(1+W7)*H6 -> 130316.73 | J6: =(1+X7)*I6 -> 142656.2 | K6: =(1+Y7)*J6 -> 156038.04 | ... M6: =(1+AA7)*L6 -> 186224.58 | P6: NA Pharma Industry Growth | Q6: 0.065 | R6: 0.065 | S6: 0.065 | T6: 0.065 | U6: 0.065 | V6: 0.065 | W6: =V6-(0.065-$AA$6)/5 -> 0.062 | X6: =W6-(0.065-$AA$6)/5 -> 0.059 | Y6: =X6-(0.065-$AA$6)/5 -> 0.056 | Z6: =Y6-(0.065-$AA$6)/5 -> 0.053 | AA6: 0.05
B7: India Business | C7: 150340.23 | D7: =1.08*C7 -> 162367.45 | E7: =1.08*D7 -> 175356.85 | F7: =1.08*E7 -> 189385.4 | G7: =1.08*F7 -> 204536.23 | H7: =1.08*G7 -> 220899.13 | I7: =1.12*H7 -> 247407.02 | J7: =1.12*I7 -> 277095.87 | K7: =1.12*J7 -> 310347.37 | L7: =1.12*K7 -> 347589.06 | M7: =1.12*L7 -> 389299.74 | P7: Best Case - US Generics Growth | R7: =((1+R5)*(1+R6))-1 -> 0.0874715 | S7: =((1+S5)*(1+S6))-1 -> 0.089708 | T7: =((1+T5)*(1+T6))-1 -> 0.0919445 | U7: =((1+U5)*(1+U6))-1 -> 0.094181 | V7: =((1+V5)*(1+V6))-1 -> 0.0964175 | W7: =((1+W5)*(1+W6))-1 -> 0.0955592 | X7: =((1+X5)*(1+X6))-1 -> 0.0946883 | Y7: =((1+Y5)*(1+Y6))-1 -> 0.0938048 | ... AA7: =((1+AA5)*(1+AA6))-1 -> 0.092
B8: Emerging Markets | C8: 87294.33 | D8: =C8*(1+R8) -> 96023.763 | E8: =D8*(1+S8) -> 106586.38 | F8: =E8*(1+T8) -> 119021.45 | G8: =F8*(1+U8) -> 133436.27 | H8: =G8*(1+V8) -> 150782.99 | I8: =H8*(1+W8) -> 170384.78 | J8: =I8*(1+X8) -> 192534.8 | K8: =J8*(1+Y8) -> 217564.32 | ... M8: =L8*(1+AA8) -> 277807.89 | P8: Emerging Market | R8: 0.1 | S8: =R8+($V$8-R8)/3 -> 0.11 | T8: =S8+($V$8-S8)/3 -> 0.11666667 | U8: =T8+($V$8-T8)/3 -> 0.12111111 | V8: 0.13 | W8: 0.13 | X8: 0.13 | Y8: 0.13 | Z8: 0.13 | AA8: 0.13
B9: Rest Of World | C9: 67895.59 | D9: =1.055*C9 -> 71629.847 | E9: =1.055*D9 -> 75569.489 | F9: =1.055*E9 -> 79725.811 | G9: =1.055*F9 -> 84110.731 | H9: =1.055*G9 -> 88736.821 | I9: =1.055*H9 -> 93617.346 | J9: =1.055*I9 -> 98766.3 | K9: =1.055*J9 -> 104198.45 | ... M9: =1.055*L9 -> 115975.48 | P9: India Business | R9: 0.08 | S9: 0.08 | T9: 0.08 | U9: 0.08 | V9: 0.08 | W9: 0.12 | X9: 0.12 | Y9: 0.12 | Z9: 0.12 | AA9: 0.12
B10: API and others | C10: 24248.425 | D10: =1.11*C10 -> 26915.752 | E10: =1.11*D10 -> 29876.484 | F10: =1.11*E10 -> 33162.898 | G10: =1.11*F10 -> 36810.816 | H10: =1.11*G10 -> 40860.006 | I10: =1.11*H10 -> 45354.607 | J10: =1.11*I10 -> 50343.614 | K10: =1.11*J10 -> 55881.411 | ... M10: =1.11*L10 -> 68851.487 | P10: Rest Of World | R10: 0.055 | S10: 0.055 | T10: 0.055 | U10: 0.055 | V10: 0.055 | W10: 0.055 | X10: 0.055 | Y10: 0.055 | Z10: 0.055 | AA10: 0.055
B11: Total (Operations) | C11: =SUM(C5:C10) -> 484968.5 | D11: =SUM(D5:D10) -> 538470.47 | E11: =SUM(E5:E10) -> 600949.53 | F11: =SUM(F5:F10) -> 673894.11 | G11: =SUM(G5:G10) -> 759192.55 | H11: =SUM(H5:H10) -> 859989.95 | I11: =SUM(I5:I10) -> 979780.76 | J11: =SUM(J5:J10) -> 1110178.4 | ... M11: =SUM(M5:M10) -> 1545365.7 | P11: U.S. Speciality | R11: 0.25 | S11: 0.25 | T11: 0.25 | U11: 0.25 | V11: 0.25 | W11: =V11-(0.25-0.104)/5 -> 0.2208 | X11: =W11-(0.25-0.104)/5 -> 0.1916 | Y11: =X11-(0.25-0.104)/5 -> 0.1624 | Z11: =Y11-(0.25-0.104)/5 -> 0.1332 | AA11: =Z11-(0.25-0.104)/5 -> 0.104
C12: =C11/10 -> 48496.85
C13: =C11/1000 -> 484.9685 | J13: Worst Case
T15: worst case
A16: Revenue | B16: In Rs Mn | C16: 2024 | D16: 2025* | E16: 2026* | F16: 2027* | G16: 2028* | H16: 2029* | I16: 2030* | J16: 2031* | K16: 2032* | L16: 2033* | M16: 2034* | P16: In Rs Mn | Q16: 2024 | R16: 2025* | S16: 2026* | T16: 2027* | U16: 2028* | V16: 2029* | W16: 2030* | X16: 2031* | Y16: 2032* | Z16: 2033* | AA16: 2034*
B17: U.S. Speciality | C17: 78564.897 | D17: =1.052*C17 -> 82650.272 | E17: =1.052*D17 -> 86948.086 | F17: =1.052*E17 -> 91469.386 | G17: =1.052*F17 -> 96225.794 | H17: =1.052*G17 -> 101229.54 | I17: =1.052*H17 -> 106493.47 | J17: =1.052*I17 -> 112031.13 | K17: =1.052*J17 -> 117856.75 | ... M17: =1.052*L17 -> 130432.54 | P17: ANDA Growth | Q17: 0.019 | R17: 0.0211 | S17: 0.0232 | T17: 0.0253 | U17: 0.0274 | V17: 0.0295 | W17: 0.0316 | X17: 0.0337 | Y17: 0.0358 | Z17: 0.0379 | AA17: 0.04
B18: U.S. Generics | C18: 76625.023 | D18: =1.065*C18 -> 81605.649 | E18: =1.065*D18 -> 86910.017 | F18: =1.065*E18 -> 92559.168 | G18: =1.065*F18 -> 98575.514 | H18: =1.065*G18 -> 104982.92 | I18: =1.05*H18 -> 110232.07 | J18: =1.05*I18 -> 115743.67 | K18: =1.05*J18 -> 121530.86 | L18: =1.05*K18 -> 127607.4 | M18: =1.05*L18 -> 133987.77 | P18: NA Pharma Industry Growth | Q18: 0.065 | R18: 0.065 | S18: 0.065 | T18: 0.065 | U18: 0.065 | V18: 0.065 | W18: 0.062 | X18: 0.059 | Y18: 0.056 | Z18: 0.053 | AA18: 0.05
B19: India Business | C19: 150340.23 | D19: =1.08*C19 -> 162367.45 | E19: =1.08*D19 -> 175356.85 | F19: =1.08*E19 -> 189385.4 | G19: =1.08*F19 -> 204536.23 | H19: =1.08*G19 -> 220899.13 | I19: =1.08*H19 -> 238571.06 | J19: =1.08*I19 -> 257656.74 | K19: =1.08*J19 -> 278269.28 | ... M19: =1.08*L19 -> 324573.29 | P19: Worst Case - US Generics Growth | Q19: 0.065 | R19: 0.065 | S19: 0.065 | T19: 0.065 | U19: 0.065 | V19: 0.05 | W19: 0.05 | X19: 0.05 | Y19: 0.05 | Z19: 0.05 | AA19: 0.05
B20: Emerging Markets | C20: 87294.33 | D20: =1.1*C20 -> 96023.763 | E20: =1.1*D20 -> 105626.14 | F20: =1.1*E20 -> 116188.75 | G20: =1.1*F20 -> 127807.63 | H20: =1.1*G20 -> 140588.39 | I20: =1.1*H20 -> 154647.23 | J20: =1.1*I20 -> 170111.95 | K20: =1.1*J20 -> 187123.15 | ... M20: =1.1*L20 -> 226419.01 | P20: Emerging Market | R20: 0.1 | S20: 0.1 | T20: 0.1 | U20: 0.1 | V20: 0.1 | W20: 0.1 | X20: 0.1 | Y20: 0.1 | Z20: 0.1 | AA20: 0.1
B21: Rest Of World | C21: 67895.59 | D21: =1.055*C21 -> 71629.847 | E21: =1.055*D21 -> 75569.489 | F21: =1.055*E21 -> 79725.811 | G21: =1.055*F21 -> 84110.731 | H21: =1.055*G21 -> 88736.821 | I21: =1.055*H21 -> 93617.346 | J21: =1.055*I21 -> 98766.3 | K21: =1.055*J21 -> 104198.45 | ... M21: =1.055*L21 -> 115975.48 | P21: India Business | R21: 0.08 | S21: 0.08 | T21: 0.08 | U21: 0.08 | V21: 0.08 | W21: 0.08 | X21: 0.08 | Y21: 0.08 | Z21: 0.08 | AA21: 0.08
B22: API and others | C22: 24248.425 | D22: =1.03*C22 -> 24975.878 | E22: =1.03*D22 -> 25725.154 | F22: =1.03*E22 -> 26496.909 | G22: =1.03*F22 -> 27291.816 | H22: =1.03*G22 -> 28110.57 | I22: =1.03*H22 -> 28953.888 | J22: =1.03*I22 -> 29822.504 | K22: =1.03*J22 -> 30717.179 | ... M22: =1.03*L22 -> 32587.856 | P22: Rest Of World | R22: 0.055 | S22: 0.055 | T22: 0.055 | U22: 0.055 | V22: 0.055 | W22: 0.055 | X22: 0.055 | Y22: 0.055 | Z22: 0.055 | AA22: 0.055
B23: Total (Operations) | C23: =SUM(C17:C22) -> 484968.5 | D23: =SUM(D17:D22) -> 519252.86 | E23: =SUM(E17:E22) -> 556135.74 | F23: =SUM(F17:F22) -> 595825.43 | G23: =SUM(G17:G22) -> 638547.71 | H23: =SUM(H17:H22) -> 684547.37 | I23: =SUM(I17:I22) -> 732515.06 | J23: =SUM(J17:J22) -> 784132.3 | ... M23: =SUM(M17:M22) -> 963975.94 | P23: API and others | R23: 0.03 | S23: 0.03 | T23: 0.03 | U23: 0.03 | V23: 0.03 | W23: 0.03 | X23: 0.03 | Y23: 0.03 | Z23: 0.03 | AA23: 0.03
J25: Base Case
T27: base case
A28: Revenue | B28: In Rs Mn | C28: 2024 | D28: 2025* | E28: 2026* | F28: 2027* | G28: 2028* | H28: 2029* | I28: 2030* | J28: 2031* | K28: 2032* | L28: 2033* | M28: 2034* | P28: In Rs Mn | Q28: 2024 | R28: 2025* | S28: 2026* | T28: 2027* | U28: 2028* | V28: 2029* | W28: 2030* | X28: 2031* | Y28: 2032* | Z28: 2033* | AA28: 2034*
B29: U.S. Speciality | C29: 78564.897 | D29: =(1+R36)*C29 -> 98206.121 | E29: =(1+S36)*D29 -> 122757.65 | F29: =(1+T36)*E29 -> 153447.06 | G29: =(1+U36)*F29 -> 191808.83 | H29: =(1+V36)*G29 -> 239761.04 | I29: =(1+W36)*H29 -> 290206.76 | J29: =(1+X36)*I29 -> 339774.08 | K29: =(1+Y36)*J29 -> 384352.43 | ... M29: =(1+AA36)*L29 -> 441376.19 | P29: ANDA Growth | Q29: 0.019 | R29: 0.019 | S29: 0.019 | T29: 0.019 | U29: 0.019 | V29: 0.019 | W29: 0.019 | X29: 0.019 | Y29: 0.019 | Z29: 0.019 | AA29: 0.019
B30: U.S. Generics | C30: 76625.023 | D30: =(1+R31)*C30 -> 83156.157 | E30: =(1+S31)*D30 -> 90243.972 | F30: =(1+T31)*E30 -> 97935.917 | G30: =(1+U31)*F30 -> 106283.48 | H30: =(1+V31)*G30 -> 115342.56 | I30: =(1+W31)*H30 -> 124821.18 | J30: =(1+X31)*I30 -> 134697.15 | K30: =(1+Y31)*J30 -> 144942.76 | ... M30: =(1+AA31)*L30 -> 166403.54 | P30: NA Pharma Industry Growth | Q30: 0.065 | R30: 0.065 | S30: 0.065 | T30: 0.065 | U30: 0.065 | V30: 0.065 | W30: 0.062 | X30: 0.059 | Y30: 0.056 | Z30: 0.053 | AA30: 0.05
B31: India Business | C31: 150340.23 | D31: =(1+R33)*C31 -> 162367.45 | E31: =(1+S33)*D31 -> 175356.85 | F31: =(1+T33)*E31 -> 189385.4 | G31: =(1+U33)*F31 -> 204536.23 | H31: =(1+V33)*G31 -> 220899.13 | I31: =(1+W33)*H31 -> 240338.25 | J31: =(1+X33)*I31 -> 263410.72 | K31: =(1+Y33)*J31 -> 290805.44 | ... M31: =(1+AA33)*L31 -> 362180.73 | P31: Base Case - US Generics Growth | R31: =((1+R29)*(1+R30))-1 -> 0.085235 | S31: =((1+S29)*(1+S30))-1 -> 0.085235 | T31: =((1+T29)*(1+T30))-1 -> 0.085235 | U31: =((1+U29)*(1+U30))-1 -> 0.085235 | V31: =((1+V29)*(1+V30))-1 -> 0.085235 | W31: =((1+W29)*(1+W30))-1 -> 0.082178 | X31: =((1+X29)*(1+X30))-1 -> 0.079121 | Y31: =((1+Y29)*(1+Y30))-1 -> 0.076064 | ... AA31: =((1+AA29)*(1+AA30))-1 -> 0.06995
B32: Emerging Markets | C32: 87294.33 | D32: =(1+R32)*C32 -> 96023.763 | E32: =(1+S32)*D32 -> 105946.22 | F32: =(1+T32)*E32 -> 117247.15 | G32: =(1+U32)*F32 -> 130144.33 | H32: =(1+V32)*G32 -> 144894.03 | I32: =(1+W32)*H32 -> 161798.33 | J32: =(1+X32)*I32 -> 181214.13 | K32: =(1+Y32)*J32 -> 203563.87 | ... M32: =(1+AA32)*L32 -> 259163.95 | P32: Emerging Market | R32: 0.1 | S32: =R32+(0.13-0.1)/9 -> 0.10333333 | T32: =S32+(0.13-0.1)/9 -> 0.10666667 | U32: =T32+(0.13-0.1)/9 -> 0.11 | V32: =U32+(0.13-0.1)/9 -> 0.11333333 | W32: =V32+(0.13-0.1)/9 -> 0.11666667 | X32: =W32+(0.13-0.1)/9 -> 0.12 | Y32: =X32+(0.13-0.1)/9 -> 0.12333333 | Z32: =Y32+(0.13-0.1)/9 -> 0.12666667 | AA32: =Z32+(0.13-0.1)/9 -> 0.13
B33: Rest Of World | C33: 67895.59 | D33: =1.055*C33 -> 71629.847 | E33: =1.055*D33 -> 75569.489 | F33: =1.055*E33 -> 79725.811 | G33: =1.055*F33 -> 84110.731 | H33: =1.055*G33 -> 88736.821 | I33: =1.055*H33 -> 93617.346 | J33: =1.055*I33 -> 98766.3 | K33: =1.055*J33 -> 104198.45 | ... M33: =1.055*L33 -> 115975.48 | P33: India Business | R33: 0.08 | S33: 0.08 | T33: 0.08 | U33: 0.08 | V33: 0.08 | W33: =V33+(0.12-0.08)/5 -> 0.088 | X33: =W33+(0.12-0.08)/5 -> 0.096 | Y33: =X33+(0.12-0.08)/5 -> 0.104 | Z33: =Y33+(0.12-0.08)/5 -> 0.112 | AA33: =Z33+(0.12-0.08)/5 -> 0.12
B34: API and others | C34: 24248.425 | D34: =1.07*C34 -> 25945.815 | E34: =1.07*D34 -> 27762.022 | F34: =1.07*E34 -> 29705.363 | G34: =1.07*F34 -> 31784.739 | H34: =1.07*G34 -> 34009.67 | I34: =1.07*H34 -> 36390.347 | J34: =1.07*I34 -> 38937.672 | K34: =1.07*J34 -> 41663.309 | ... M34: =1.07*L34 -> 47700.322 | P34: Rest Of World | R34: 0.055 | S34: 0.055 | T34: 0.055 | U34: 0.055 | V34: 0.055 | W34: 0.055 | X34: 0.055 | Y34: 0.055 | Z34: 0.055 | AA34: 0.055
B35: Total (Operations) | C35: =SUM(C29:C34) -> 484968.5 | D35: =SUM(D29:D34) -> 537329.16 | E35: =SUM(E29:E34) -> 597636.2 | F35: =SUM(F29:F34) -> 667446.7 | G35: =SUM(G29:G34) -> 748668.35 | H35: =SUM(H29:H34) -> 843643.24 | I35: =SUM(I29:I34) -> 947172.21 | J35: =SUM(J29:J34) -> 1056800.1 | ... M35: =SUM(M29:M34) -> 1392800.2 | P35: API and others | R35: 0.07 | S35: 0.07 | T35: 0.07 | U35: 0.07 | V35: 0.07 | W35: 0.07 | X35: 0.07 | Y35: 0.07 | Z35: 0.07 | AA35: 0.07
P36: US Speciality | R36: 0.25 | S36: 0.25 | T36: 0.25 | U36: 0.25 | V36: 0.25 | W36: =V36-(0.25-0.052)/5 -> 0.2104 | X36: =W36-(0.25-0.052)/5 -> 0.1708 | Y36: =X36-(0.25-0.052)/5 -> 0.1312 | Z36: =Y36-(0.25-0.052)/5 -> 0.0916 | AA36: =Z36-(0.25-0.052)/5 -> 0.052

Sheet FCFF (Best Case)
C2: Discounted Cashflow
A4: In Millions of INR | B4: FY 2022 | C4: FY 2023 | D4: FY 2024 | E4: FY 2025 | F4: FY 2026 | G4: FY 2027 | H4: FY 2028 | I4: FY 2029 | J4: FY 2030 | K4: FY 2031 | L4: FY 2032 | M4: FY 2033 | N4: FY 2034
A5: Revenue | B5: 384264.2 | C5: 432788.7 | D5: 477584.5 | S5: GDP growth
Q6: 0.31 | R6: India | S6: 0.04 | U6: stable growth rate
A7: + Sales & Services Revenue | B7: 384264.2 | C7: 432788.7 | D7: ='Revenue Projection'!C11 -> 484968.5 | E7: ='Revenue Projection'!D11 -> 538470.47 | F7: ='Revenue Projection'!E11 -> 600949.53 | G7: ='Revenue Projection'!F11 -> 673894.11 | H7: ='Revenue Projection'!G11 -> 759192.55 | I7: ='Revenue Projection'!H11 -> 859989.95 | J7: ='Revenue Projection'!I11 -> 979780.76 | K7: ='Revenue Projection'!J11 -> 1110178.4 | ... N7: ='Revenue Projection'!M11 -> 1545365.7 | Q7: 0.32 | R7: US | S7: 0.02 | U7: =Q6*S6+Q7*S7+Q8*S8 -> 0.03068
A8: Gross Profit | B8: — | C8: — | D8: — | Q8: =1-Q7-Q7 -> 0.36 | R8: Rest of the world | S8: 0.033
A9: + Other Operating Income | B9: 2280.7 | C9: 6068.1 | D9: 7384
A10: - Operating Expenses | B10: 301582.5 | C10: 344470.2 | D10: 378009.5
A11: + Selling & Marketing | B11: 32817.3 | C11: 42921.8 | D11: 49677.9 | E11: =E7*$E$12 -> 53847.047 | F11: =F7*$E$12 -> 60094.953 | G11: =G7*$E$12 -> 67389.411 | H11: =H7*$E$12 -> 75919.255 | I11: =I7*$E$12 -> 85998.995
B12: 0.08540296 | C12: 0.099174955 | D12: =D11/D7 -> 0.10243531 | E12: 0.1
A13: + Research & Development | B13: 22103.7 | C13: 22856.2 | D13: 30923.7 | E13: =E7*$E$14 -> 35000.58 | F13: =F7*$E$14 -> 39061.719 | G13: =G7*$E$14 -> 43803.117 | H13: =H7*$E$14 -> 49347.516 | I13: =I7*$E$14 -> 55899.347
E14: 0.065
A15: Amortised R&D | B15: 6323.73 | C15: 8609.35 | D15: =C15+D13/10 -> 11701.72 | E15: =D15+E13/10 -> 15201.778 | F15: =E15+F13/10 -> 19107.95 | G15: =F15+G13/10 -> 23488.262 | H15: =G15+H13/10 -> 28423.013 | I15: =H15+I13/10 -> 34012.948
A16: Unamortised R&D | B16: 50831.18 | C16: 65078.03 | D16: =C16+D13-D15 -> 84300.01 | E16: =D16+E13-E15 -> 104098.81 | F16: =E16+F13-F15 -> 124052.58 | G16: =F16+G13-G15 -> 144367.44 | H16: =G16+H13-H15 -> 165291.94 | I16: =H16+I13-I15 -> 187178.34
A18: + Depreciation & Amortization | B18: 21437.4 | C18: 25294.3 | D18: 25566.4 | E18: =E7*$E$19 -> 32308.228 | F18: =F7*$E$19 -> 36056.972 | G18: =G7*$E$19 -> 40433.646 | H18: =H7*$E$19 -> 45551.553 | I18: =I7*$E$19 -> 51599.397 | J18: =J7*$E$19 -> 58786.846 | K18: =K7*$E$19 -> 66610.706 | L18: =L7*$E$19 -> 74967.203 | ... N18: =N7*$E$19 -> 92721.944
B19: 0.055788179 | C19: 0.058444918 | D19: =D18/D7 -> 0.052717651 | E19: 0.06
A20: + Prov For Doubtful Accts | B20: 175.7 | C20: 426.2 | D20: 905.9 | E20: =E7*$E$21 -> 1076.9409 | F20: =F7*$E$21 -> 1201.8991 | G20: =G7*$E$21 -> 1347.7882 | H20: =H7*$E$21 -> 1518.3851 | I20: =I7*$E$21 -> 1719.9799
B21: 0.00045723749 | C21: 0.00098477617 | D21: =D20/D7 -> 0.0018679564 | E21: 0.002
A22: + Other Operating Expense | B22: 225048.4 | C22: 252971.7 | D22: 270935.6 | E22: =E7*E23 -> 301543.46 | F22: =F7*F23 -> 330522.24 | G22: =G7*G23 -> 363902.82 | H22: =H7*H23 -> 402372.05 | I22: =I7*I23 -> 447194.78
B23: 0.58566059 | C23: 0.58451549 | D23: =D22/D7 -> 0.55866639 | E23: 0.56 | F23: 0.55 | G23: 0.54 | H23: 0.53 | I23: 0.52
A24: Operating Income (Loss) | B24: 84962.4 | C24: 94386.6 | D24: 106959 | E24: =E7-(E11+E13+E18+E20+E22) -> 114694.21 | F24: =F7-(F11+F13+F18+F20+F22) -> 134011.74 | G24: =G7-(G11+G13+G18+G20+G22) -> 157017.33 | H24: =H7-(H11+H13+H18+H20+H22) -> 184483.79 | I24: =I7-(I11+I13+I18+I20+I22) -> 217577.46
A25: Adjusted op income (R&D capitalized) | B25: 135793.58 | C25: 159464.63 | D25: =D24+D16 -> 191259.01 | E25: =E24+E16 -> 218793.02 | F25: =F24+F16 -> 258064.33 | G25: =G24+G16 -> 301384.76 | H25: =H24+H16 -> 349775.73 | I25: =I24+I16 -> 404755.8 | J25: =J7*J26 -> 470294.77 | K25: =K7*K26 -> 543987.43 | L25: =L7*L26 -> 624726.69 | M25: =M7*M26 -> 697678.02 | N25: =N7*N26 -> 772682.87
B26: 0.35338598 | C26: 0.3684584 | D26: =D25/D7 -> 0.39437409 | E26: =E25/E7 -> 0.40632316 | F26: =F25/F7 -> 0.42942762 | G26: =G25/G7 -> 0.44722867 | H26: =H25/H7 -> 0.46072071 | I26: =I25/I7 -> 0.47065177 | J26: 0.48 | K26: 0.49 | L26: 0.5 | M26: 0.5 | N26: 0.5
A27: - Non-Operating (Income) Loss | B27: -8501.8 | C27: -1645.5 | D27: -10388.6 | E27: =E7*$E$30 -> -5384.7047 | F27: =F7*$E$30 -> -6009.4953 | G27: =G7*$E$30 -> -6738.9411 | H27: =H7*$E$30 -> -7591.9255 | I27: =I7*$E$30 -> -8599.8995
A28: effective tax rate | B28: marginal tax rate | C28: 0.25
A29: post tax operating income | B29: 88341.871 | C29: 103741.31 | D29: =D25*(1-0.34944) -> 124425.46 | E29: =E25*(1-0.34944) -> 142337.99 | F29: =F25*(1-0.34944) -> 167886.33 | G29: =G25*(1-0.34944) -> 196068.87 | H29: =H25*(1-0.34944) -> 227550.1 | I29: =I25*(1-0.34944) -> 263317.93 | J29: =J25*(1-0.34944) -> 305954.96 | K29: =K25*(1-0.34944) -> 353896.46 | ... N29: =N25*(1-0.34944) -> 502676.57
B30: -0.022124882 | C30: -0.0038020863 | D30: =D27/D7 -> -0.021421185 | E30: -0.01
A31: Add: depn and ammortization | B31: 109779.27 | C31: 129035.61 | D31: =D29+D18 -> 149991.86 | E31: =E29+E18 -> 174646.22 | F31: =F29+F18 -> 203943.3 | G31: =G29+G18 -> 236502.52 | H31: =H29+H18 -> 273101.65 | I31: =I29+I18 -> 314917.33 | J31: =J29+J18 -> 364741.81 | K31: =K29+K18 -> 420507.17 | ... N31: =N29+N18 -> 595398.51
A32: Capex | B32: -26.2 | C32: 1848.4 | D32: -536.8 | E32: 0 | F32: 0 | G32: 0 | H32: 0 | I32: 0 | J32: 0 | K32: 0 | L32: 0 | M32: 0 | N32: 0
A33: % capex of revenue | B33: -6.8182256e-05 | C33: 0.0042709063 | D33: =D32/D7 -> -0.001106876 | E33: 0
A34: Change in Net working capital | B34: 26013.3 | C34: 71012.4 | D34: -15920.5 | E34: -82770.041 | F34: 18851.343 | G34: 99055.715 | H34: -23686.022 | I34: -122448.02 | J34: 28893.705 | K34: 137195.27 | L34: -34550.015 | M34: -162822.73 | N34: 40747.167
A35: FCFF | B35: 83792.171 | C35: 56174.81 | D35: =D31-D32-D34 -> 166449.16 | E35: =E31-E32-E34 -> 257416.26 | F35: =F31-F32-F34 -> 185091.96 | G35: =G31-G32-G34 -> 137446.8 | H35: =H31-H32-H34 -> 296787.67 | I35: =I31-I32-I34 -> 437365.34 | J35: =J31-J32-J34 -> 335848.1 | K35: =K31-K32-K34 -> 283311.9 | ... N35: =N31-N32-N34 -> 554651.34
A36: Terminal Value | N36: =N35*(1+U7)/(B38-U7) -> 9071090.4
A37: Cash Flows | B37: =B35+B36 -> 83792.171 | C37: =C35+C36 -> 56174.81 | D37: =D35+D36 -> 166449.16 | E37: =E35+E36 -> 257416.26 | F37: =F35+F36 -> 185091.96 | G37: =G35+G36 -> 137446.8 | H37: =H35+H36 -> 296787.67 | I37: =I35+I36 -> 437365.34 | ... N37: =N35+N36 -> 9625741.8
A38: WACC | B38: =WACC!D28 -> 0.093700874
A39: Discount Factor | B39: - | C39: - | D39: 1 | E39: =1/(1+$B$38)^1 -> 0.91432678 | F39: =1/(1+$B$38)^2 -> 0.83599346 | G39: =1/(1+$B$38)^3 -> 0.76437121 | H39: =1/(1+$B$38)^4 -> 0.69888507 | I39: =1/(1+$B$38)^5 -> 0.63900934 | J39: =1/(1+$B$38)^6 -> 0.58426335 | K39: =1/(1+$B$38)^7 -> 0.53420763 | L39: =1/(1+$B$38)^8 -> 0.48844034 | M39: =1/(1+$B$38)^9 -> 0.44659409 | N39: =1/(1+$B$38)^10 -> 0.40833293
A40: EV without TV | B40: =SUMPRODUCT(D35:N35,D39:N39) -> 2287373.8
A41: Enterprice Value | B41: =SUMPRODUCT(D37:N37,D39:N39) -> 5991398.8
A42: Implied Share Price_2nd_Method | B42: =((B40+(N35*(1+U7)/(B38-U7)/(1+$B$38)^10))-B43+B44)/B47 -> 2535.7459
A43: Less: BV of debt | B43: 3036.2
...

Sheet FCFF (Worst Case)
C2: Discounted Cashflow
A4: In Millions of INR | B4: FY 2022 | C4: FY 2023 | D4: FY 2024 | E4: FY 2025 | F4: FY 2026 | G4: FY 2027 | H4: FY 2028 | I4: FY 2029 | J4: FY 2030 | K4: FY 2031 | L4: FY 2032 | M4: FY 2033 | N4: FY 2034
A5: Revenue | B5: 384264.2 | C5: 432788.7 | D5: 477584.5 | S5: GDP growth
Q6: 0.31 | R6: India | S6: 0.04 | U6: stable growth rate
A7: + Sales & Services Revenue | B7: 384264.2 | C7: 432788.7 | D7: ='Revenue Projection'!C23 -> 484968.5 | E7: ='Revenue Projection'!D23 -> 519252.86 | F7: ='Revenue Projection'!E23 -> 556135.74 | G7: ='Revenue Projection'!F23 -> 595825.43 | H7: ='Revenue Projection'!G23 -> 638547.71 | I7: ='Revenue Projection'!H23 -> 684547.37 | J7: ='Revenue Projection'!I23 -> 732515.06 | K7: ='Revenue Projection'!J23 -> 784132.3 | ... N7: ='Revenue Projection'!M23 -> 963975.94 | Q7: 0.32 | R7: US | S7: 0.02 | U7: =Q6*S6+Q7*S7+Q8*S8 -> 0.03068
A8: Gross Profit | B8: — | C8: — | D8: — | Q8: =1-Q7-Q7 -> 0.36 | R8: Rest of the world | S8: 0.033
A9: + Other Operating Income | B9: 2280.7 | C9: 6068.1 | D9: 7384
A10: - Operating Expenses | B10: 301582.5 | C10: 344470.2 | D10: 378009.5
A11: + Selling & Marketing | B11: 32817.3 | C11: 42921.8 | D11: 49677.9 | E11: =E7*$E$12 -> 51925.286 | F11: =F7*$E$12 -> 55613.574 | G11: =G7*$E$12 -> 59582.543 | H11: =H7*$E$12 -> 63854.771 | I11: =I7*$E$12 -> 68454.737
B12: 0.08540296 | C12: 0.099174955 | D12: =D11/D7 -> 0.10243531 | E12: 0.1
A13: + Research & Development | B13: 22103.7 | C13: 22856.2 | D13: 30923.7 | E13: =E7*$E$14 -> 33751.436 | F13: =F7*$E$14 -> 36148.823 | G13: =G7*$E$14 -> 38728.653 | H13: =H7*$E$14 -> 41505.601 | I13: =I7*$E$14 -> 44495.579
E14: 0.065
A15: Amortised R&D | B15: 6323.73 | C15: 8609.35 | D15: =C15+D13/10 -> 11701.72 | E15: =D15+E13/10 -> 15076.864 | F15: =E15+F13/10 -> 18691.746 | G15: =F15+G13/10 -> 22564.611 | H15: =G15+H13/10 -> 26715.171 | I15: =H15+I13/10 -> 31164.729
A16: Unamortised R&D | B16: 50831.18 | C16: 65078.03 | D16: =C16+D13-D15 -> 84300.01 | E16: =D16+E13-E15 -> 102974.58 | F16: =E16+F13-F15 -> 120431.66 | G16: =F16+G13-G15 -> 136595.7 | H16: =G16+H13-H15 -> 151386.13 | I16: =H16+I13-I15 -> 164716.98
A18: + Depreciation & Amortization | B18: 21437.4 | C18: 25294.3 | D18: 25566.4 | E18: =E7*$E$19 -> 31155.172 | F18: =F7*$E$19 -> 33368.144 | G18: =G7*$E$19 -> 35749.526 | H18: =H7*$E$19 -> 38312.863 | I18: =I7*$E$19 -> 41072.842 | J18: =J7*$E$19 -> 43950.904 | K18: =K7*$E$19 -> 47047.938 | L18: =L7*$E$19 -> 50381.74 | ... N18: =N7*$E$19 -> 57838.556
B19: 0.055788179 | C19: 0.058444918 | D19: =D18/D7 -> 0.052717651 | E19: 0.06
A20: + Prov For Doubtful Accts | B20: 175.7 | C20: 426.2 | D20: 905.9 | E20: =E7*$E$21 -> 1038.5057 | F20: =F7*$E$21 -> 1112.2715 | G20: =G7*$E$21 -> 1191.6509 | H20: =H7*$E$21 -> 1277.0954 | I20: =I7*$E$21 -> 1369.0947
B21: 0.00045723749 | C21: 0.00098477617 | D21: =D20/D7 -> 0.0018679564 | E21: 0.002
A22: + Other Operating Expense | B22: 225048.4 | C22: 252971.7 | D22: 270935.6 | E22: =E7*E23 -> 290781.6 | F22: =F7*F23 -> 305874.65 | G22: =G7*G23 -> 321745.73 | H22: =H7*H23 -> 338430.29 | I22: =I7*I23 -> 355964.63
B23: 0.58566059 | C23: 0.58451549 | D23: =D22/D7 -> 0.55866639 | E23: 0.56 | F23: 0.55 | G23: 0.54 | H23: 0.53 | I23: 0.52
A24: Operating Income (Loss) | B24: 84962.4 | C24: 94386.6 | D24: 106959 | E24: =E7-(E11+E13+E18+E20+E22) -> 110600.86 | F24: =F7-(F11+F13+F18+F20+F22) -> 124018.27 | G24: =G7-(G11+G13+G18+G20+G22) -> 138827.32 | H24: =H7-(H11+H13+H18+H20+H22) -> 155167.09 | I24: =I7-(I11+I13+I18+I20+I22) -> 173190.48
A25: Adjusted op income (R&D capitalized) | B25: 135793.58 | C25: 159464.63 | D25: =D24+D16 -> 191259.01 | E25: =E24+E16 -> 213575.44 | F25: =F24+F16 -> 244449.93 | G25: =G24+G16 -> 275423.02 | H25: =H24+H16 -> 306553.23 | I25: =I24+I16 -> 337907.46 | J25: =J7*J26 -> 351607.23 | K25: =K7*K26 -> 384224.83 | L25: =L7*L26 -> 419847.83 | M25: =M7*M26 -> 449763.52 | N25: =N7*N26 -> 481987.97
B26: 0.35338598 | C26: 0.3684584 | D26: =D25/D7 -> 0.39437409 | E26: =E25/E7 -> 0.41131298 | F26: =F25/F7 -> 0.43955084 | G26: =G25/G7 -> 0.46225457 | H26: =H25/H7 -> 0.48007881 | I26: =I25/I7 -> 0.49362174 | J26: 0.48 | K26: 0.49 | L26: 0.5 | M26: 0.5 | N26: 0.5
A27: - Non-Operating (Income) Loss | B27: -8501.8 | C27: -1645.5 | D27: -10388.6 | E27: =E7*$E$30 -> -5192.5286 | F27: =F7*$E$30 -> -5561.3574 | G27: =G7*$E$30 -> -5958.2543 | H27: =H7*$E$30 -> -6385.4771 | I27: =I7*$E$30 -> -6845.4737
A28: effective tax rate | B28: marginal tax rate | C28: 0.25
A29: post tax operating income | B29: 88341.871 | C29: 103741.31 | D29: =D25*(1-0.34944) -> 124425.46 | E29: =E25*(1-0.34944) -> 138943.64 | F29: =F25*(1-0.34944) -> 159029.35 | G29: =G25*(1-0.34944) -> 179179.2 | H29: =H25*(1-0.34944) -> 199431.27 | I29: =I25*(1-0.34944) -> 219829.08 | J29: =J25*(1-0.34944) -> 228741.6 | K29: =K25*(1-0.34944) -> 249961.3 | ... N29: =N25*(1-0.34944) -> 313562.09
B30: -0.022124882 | C30: -0.0038020863 | D30: =D27/D7 -> -0.021421185 | E30: -0.01
A31: Add: depn and ammortization | B31: 109779.27 | C31: 129035.61 | D31: =D29+D18 -> 149991.86 | E31: =E29+E18 -> 170098.81 | F31: =F29+F18 -> 192397.49 | G31: =G29+G18 -> 214928.73 | H31: =H29+H18 -> 237744.13 | I31: =I29+I18 -> 260901.92 | J31: =J29+J18 -> 272692.5 | K31: =K29+K18 -> 297009.24 | ... N31: =N29+N18 -> 371400.65
A32: Capex | B32: -26.2 | C32: 1848.4 | D32: -536.8 | E32: 0 | F32: 0 | G32: 0 | H32: 0 | I32: 0 | J32: 0 | K32: 0 | L32: 0 | M32: 0 | N32: 0
A33: % capex of revenue | B33: -6.8182256e-05 | C33: 0.0042709063 | D33: =D32/D7 -> -0.001106876 | E33: 0
A34: Change in Net working capital | B34: 26013.3 | C34: 71012.4 | D34: -15920.5 | E34: -82770.041 | F34: 18851.343 | G34: 99055.715 | H34: -23686.022 | I34: -122448.02 | J34: 28893.705 | K34: 137195.27 | L34: -34550.015 | M34: -162822.73 | N34: 40747.167
A35: FCFF | B35: 83792.171 | C35: 56174.81 | D35: =D31-D32-D34 -> 166449.16 | E35: =E31-E32-E34 -> 252868.85 | F35: =F31-F32-F34 -> 173546.15 | G35: =G31-G32-G34 -> 115873.01 | H35: =H31-H32-H34 -> 261430.15 | I35: =I31-I32-I34 -> 383349.94 | J35: =J31-J32-J34 -> 243798.8 | K35: =K31-K32-K34 -> 159813.97 | ... N35: =N31-N32-N34 -> 330653.48
A36: Terminal Value | N36: =N35*(1+U7)/(B38-U7) -> 5407699.2
A37: Cash Flows | B37: =B35+B36 -> 83792.171 | C37: =C35+C36 -> 56174.81 | D37: =D35+D36 -> 166449.16 | E37: =E35+E36 -> 252868.85 | F37: =F35+F36 -> 173546.15 | G37: =G35+G36 -> 115873.01 | H37: =H35+H36 -> 261430.15 | I37: =I35+I36 -> 383349.94 | ... N37: =N35+N36 -> 5738352.7
A38: WACC | B38: =WACC!D28 -> 0.093700874
A39: Discount Factor | B39: - | C39: - | D39: 1 | E39: =1/(1+$B$38)^1 -> 0.91432678 | F39: =1/(1+$B$38)^2 -> 0.83599346 | G39: =1/(1+$B$38)^3 -> 0.76437121 | H39: =1/(1+$B$38)^4 -> 0.69888507 | I39: =1/(1+$B$38)^5 -> 0.63900934 | J39: =1/(1+$B$38)^6 -> 0.58426335 | K39: =1/(1+$B$38)^7 -> 0.53420763 | L39: =1/(1+$B$38)^8 -> 0.48844034 | M39: =1/(1+$B$38)^9 -> 0.44659409 | N39: =1/(1+$B$38)^10 -> 0.40833293
A40: Enterprice Value | B40: =SUMPRODUCT(D37:N37,D39:N39) -> 4032342.6
A41: Less: BV of debt | B41: 3036.2
A42: Add: Cash | B42: 105206.8
A44: Value of equity | B44: =B40-B41+B42 -> 4134513.2
...

Sheet FCFF (Base Case)
C2: Discounted Cashflow
A4: In Millions of INR | B4: FY 2022 | C4: FY 2023 | D4: FY 2024 | E4: FY 2025 | F4: FY 2026 | G4: FY 2027 | H4: FY 2028 | I4: FY 2029 | J4: FY 2030 | K4: FY 2031 | L4: FY 2032 | M4: FY 2033 | N4: FY 2034
A5: Revenue | B5: 384264.2 | C5: 432788.7 | D5: 477584.5 | S5: GDP growth
Q6: 0.31 | R6: India | S6: 0.04 | U6: stable growth rate
A7: + Sales & Services Revenue | B7: 384264.2 | C7: 432788.7 | D7: ='Revenue Projection'!C35 -> 484968.5 | E7: ='Revenue Projection'!D35 -> 537329.16 | F7: ='Revenue Projection'!E35 -> 597636.2 | G7: ='Revenue Projection'!F35 -> 667446.7 | H7: ='Revenue Projection'!G35 -> 748668.35 | I7: ='Revenue Projection'!H35 -> 843643.24 | J7: ='Revenue Projection'!I35 -> 947172.21 | K7: ='Revenue Projection'!J35 -> 1056800.1 | ... N7: ='Revenue Projection'!M35 -> 1392800.2 | Q7: 0.32 | R7: US | S7: 0.02 | U7: =Q6*S6+Q7*S7+Q8*S8 -> 0.03068
A8: Gross Profit | B8: — | C8: — | D8: — | Q8: =1-Q7-Q7 -> 0.36 | R8: Rest of the world | S8: 0.033
A9: + Other Operating Income | B9: 2280.7 | C9: 6068.1 | D9: 7384
A10: - Operating Expenses | B10: 301582.5 | C10: 344470.2 | D10: 378009.5
A11: + Selling & Marketing | B11: 32817.3 | C11: 42921.8 | D11: 49677.9 | E11: =E7*$E$12 -> 53732.916 | F11: =F7*$E$12 -> 59763.62 | G11: =G7*$E$12 -> 66744.67 | H11: =H7*$E$12 -> 74866.835 | I11: =I7*$E$12 -> 84364.324
B12: 0.08540296 | C12: 0.099174955 | D12: =D11/D7 -> 0.10243531 | E12: 0.1
A13: + Research & Development | B13: 22103.7 | C13: 22856.2 | D13: 30923.7 | E13: =E7*$E$14 -> 34926.395 | F13: =F7*$E$14 -> 38846.353 | G13: =G7*$E$14 -> 43384.036 | H13: =H7*$E$14 -> 48663.443 | I13: =I7*$E$14 -> 54836.811
E14: 0.065
A15: Amortised R&D | B15: 6323.73 | C15: 8609.35 | D15: =C15+D13/10 -> 11701.72 | E15: =D15+E13/10 -> 15194.36 | F15: =E15+F13/10 -> 19078.995 | G15: =F15+G13/10 -> 23417.398 | H15: =G15+H13/10 -> 28283.743 | I15: =H15+I13/10 -> 33767.424
A16: Unamortised R&D | B16: 50831.18 | C16: 65078.03 | D16: =C16+D13-D15 -> 84300.01 | E16: =D16+E13-E15 -> 104032.05 | F16: =E16+F13-F15 -> 123799.4 | G16: =F16+G13-G15 -> 143766.04 | H16: =G16+H13-H15 -> 164145.74 | I16: =H16+I13-I15 -> 185215.13
A18: + Depreciation & Amortization | B18: 21437.4 | C18: 25294.3 | D18: 25566.4 | E18: =E7*$E$19 -> 32239.749 | F18: =F7*$E$19 -> 35858.172 | G18: =G7*$E$19 -> 40046.802 | H18: =H7*$E$19 -> 44920.101 | I18: =I7*$E$19 -> 50618.594 | J18: =J7*$E$19 -> 56830.333 | K18: =K7*$E$19 -> 63408.003 | L18: =L7*$E$19 -> 70171.576 | ... N18: =N7*$E$19 -> 83568.012
B19: 0.055788179 | C19: 0.058444918 | D19: =D18/D7 -> 0.052717651 | E19: 0.06
A20: + Prov For Doubtful Accts | B20: 175.7 | C20: 426.2 | D20: 905.9 | E20: =E7*$E$21 -> 1074.6583 | F20: =F7*$E$21 -> 1195.2724 | G20: =G7*$E$21 -> 1334.8934 | H20: =H7*$E$21 -> 1497.3367 | I20: =I7*$E$21 -> 1687.2865
B21: 0.00045723749 | C21: 0.00098477617 | D21: =D20/D7 -> 0.0018679564 | E21: 0.002
A22: + Other Operating Expense | B22: 225048.4 | C22: 252971.7 | D22: 270935.6 | E22: =E7*E23 -> 300904.33 | F22: =F7*F23 -> 328699.91 | G22: =G7*G23 -> 360421.22 | H22: =H7*H23 -> 396794.23 | I22: =I7*I23 -> 438694.49
B23: 0.58566059 | C23: 0.58451549 | D23: =D22/D7 -> 0.55866639 | E23: 0.56 | F23: 0.55 | G23: 0.54 | H23: 0.53 | I23: 0.52
A24: Operating Income (Loss) | B24: 84962.4 | C24: 94386.6 | D24: 106959 | E24: =E7-(E11+E13+E18+E20+E22) -> 114451.11 | F24: =F7-(F11+F13+F18+F20+F22) -> 133272.87 | G24: =G7-(G11+G13+G18+G20+G22) -> 155515.08 | H24: =H7-(H11+H13+H18+H20+H22) -> 181926.41 | I24: =I7-(I11+I13+I18+I20+I22) -> 213441.74
A25: Adjusted op income (R&D capitalized) | B25: 135793.58 | C25: 159464.63 | D25: =D24+D16 -> 191259.01 | E25: =E24+E16 -> 218483.16 | F25: =F24+F16 -> 257072.28 | G25: =G24+G16 -> 299281.12 | H25: =H24+H16 -> 346072.15 | I25: =I24+I16 -> 398656.87 | J25: =J7*J26 -> 454642.66 | K25: =K7*K26 -> 517832.03 | L25: =L7*L26 -> 584763.13 | M25: =M7*M26 -> 641158.54 | N25: =N7*N26 -> 696400.1
B26: 0.35338598 | C26: 0.3684584 | D26: =D25/D7 -> 0.39437409 | E26: =E25/E7 -> 0.40660953 | F26: =F25/F7 -> 0.43014843 | G26: =G25/G7 -> 0.44839704 | H26: =H25/H7 -> 0.46225027 | I26: =I25/I7 -> 0.472542 | J26: 0.48 | K26: 0.49 | L26: 0.5 | M26: 0.5 | N26: 0.5
A27: - Non-Operating (Income) Loss | B27: -8501.8 | C27: -1645.5 | D27: -10388.6 | E27: =E7*$E$30 -> -5373.2916 | F27: =F7*$E$30 -> -5976.362 | G27: =G7*$E$30 -> -6674.467 | H27: =H7*$E$30 -> -7486.6835 | I27: =I7*$E$30 -> -8436.4324
A28: effective tax rate | B28: marginal tax rate | C28: 0.25
A29: post tax operating income | B29: 88341.871 | C29: 103741.31 | D29: =D25*(1-0.34944) -> 124425.46 | E29: =E25*(1-0.34944) -> 142136.4 | F29: =F25*(1-0.34944) -> 167240.94 | G29: =G25*(1-0.34944) -> 194700.33 | H29: =H25*(1-0.34944) -> 225140.7 | I29: =I25*(1-0.34944) -> 259350.21 | J29: =J25*(1-0.34944) -> 295772.33 | K29: =K25*(1-0.34944) -> 336880.8 | ... N29: =N25*(1-0.34944) -> 453050.05
B30: -0.022124882 | C30: -0.0038020863 | D30: =D27/D7 -> -0.021421185 | E30: -0.01
A31: Add: depn and ammortization | B31: 109779.27 | C31: 129035.61 | D31: =D29+D18 -> 149991.86 | E31: =E29+E18 -> 174376.15 | F31: =F29+F18 -> 203099.11 | G31: =G29+G18 -> 234747.13 | H31: =H29+H18 -> 270060.8 | I31: =I29+I18 -> 309968.81 | J31: =J29+J18 -> 352602.66 | K31: =K29+K18 -> 400288.81 | ... N31: =N29+N18 -> 536618.06
A32: Capex | B32: -26.2 | C32: 1848.4 | D32: -536.8 | E32: 0 | F32: 0 | G32: 0 | H32: 0 | I32: 0 | J32: 0 | K32: 0 | L32: 0 | M32: 0 | N32: 0
A33: % capex of revenue | B33: -6.8182256e-05 | C33: 0.0042709063 | D33: =D32/D7 -> -0.001106876 | E33: 0
A34: Change in Net working capital | B34: 26013.3 | C34: 71012.4 | D34: -15920.5 | E34: -82770.041 | F34: 18851.343 | G34: 99055.715 | H34: -23686.022 | I34: -122448.02 | J34: 28893.705 | K34: 137195.27 | L34: -34550.015 | M34: -162822.73 | N34: 40747.167
A35: FCFF | B35: 83792.171 | C35: 56174.81 | D35: =D31-D32-D34 -> 166449.16 | E35: =E31-E32-E34 -> 257146.19 | F35: =F31-F32-F34 -> 184247.77 | G35: =G31-G32-G34 -> 135691.41 | H35: =H31-H32-H34 -> 293746.82 | I35: =I31-I32-I34 -> 432416.82 | J35: =J31-J32-J34 -> 323708.96 | K35: =K31-K32-K34 -> 263093.53 | ... N35: =N31-N32-N34 -> 495870.9
A36: Terminal Value | N36: =N35*(1+U7)/(B38-U7) -> 8109760.8
A37: Cash Flows | B37: =B35+B36 -> 83792.171 | C37: =C35+C36 -> 56174.81 | D37: =D35+D36 -> 166449.16 | E37: =E35+E36 -> 257146.19 | F37: =F35+F36 -> 184247.77 | G37: =G35+G36 -> 135691.41 | H37: =H35+H36 -> 293746.82 | I37: =I35+I36 -> 432416.82 | ... N37: =N35+N36 -> 8605631.7
A38: WACC | B38: =WACC!D28 -> 0.093700874
A39: Discount Factor | B39: - | C39: - | D39: 1 | E39: =1/(1+$B$38)^1 -> 0.91432678 | F39: =1/(1+$B$38)^2 -> 0.83599346 | G39: =1/(1+$B$38)^3 -> 0.76437121 | H39: =1/(1+$B$38)^4 -> 0.69888507 | I39: =1/(1+$B$38)^5 -> 0.63900934 | J39: =1/(1+$B$38)^6 -> 0.58426335 | K39: =1/(1+$B$38)^7 -> 0.53420763 | L39: =1/(1+$B$38)^8 -> 0.48844034 | M39: =1/(1+$B$38)^9 -> 0.44659409 | N39: =1/(1+$B$38)^10 -> 0.40833293
A40: Enterprice Value | B40: =SUMPRODUCT(D37:N37,D39:N39) -> 5514888.1
A41: Less: BV of debt | B41: 3036.2
A42: Add: Cash | B42: 105206.8
A44: Value of equity | B44: =B40-B41+B42 -> 5617058.7
...

Sheet Fundamental Beta
B2: COMPARABLES | C2: No. of Shares Outstanding (INR Millions) | D2: Current Share price | E2: Market Cap (INR Billions) | F2: Total Debt (INR Billions) | G2: Cash & Cash Eq (INR Billions). | H2: Firm value (INR Billions) | I2: Debt/Equity (D/E) | J2: Beta | K2: Tax rate | L2: Unlevered Beta for company | M2: Cash/Firm value | N2: Estimating Unlevered beta for the Business
B3: Cipla | C3: 807.36706 | D3: 1577.45 | E3: =C3*D3/1000 -> 1273.5812 | F3: 5.5941 | G3: 56.8198 | H3: 1221.2768 | I3: =F3/E3 -> 0.0043924173 | J3: 0.452 | K3: 0.28 | L3: =J3/(1+(1-K3)*I3) -> 0.45057504 | M3: =G3/H3 -> 0.046524916 | N3: =L3/(1-M3) -> 0.47256089
B4: Zydus Lifescience | C4: 1006.234 | D4: 1206.7 | E4: =C4*D4/1000 -> 1214.2226 | F4: 8.042 | G4: 13.576 | H4: 1203.235 | I4: =F4/E4 -> 0.006623168 | J4: 0.489 | K4: 0.28 | L4: =J4/(1+(1-K4)*I4) -> 0.48667918 | M4: =G4/H4 -> 0.011282916 | N4: =L4/(1-M4) -> 0.49223301
B5: Dr. Reddy Laboratories | C5: =166.818466-0.289791 -> 166.52867 | D5: 6933.85 | E5: =C5*D5/1000 -> 1154.6849 | F5: 20.02 | G5: 61.327 | H5: 1119.063 | I5: =F5/E5 -> 0.017338064 | J5: 0.245 | K5: 0.28 | L5: =J5/(1+(1-K5)*I5) -> 0.24197927 | M5: =G5/H5 -> 0.054802098 | N5: =L5/(1-M5) -> 0.25600911
B6: Torrent Pharmaceuticals | C6: 338.44544 | D6: 3343.65 | E6: =C6*D6/1000 -> 1131.6431 | F6: 40.3937 | G6: 9.8 | H6: 1164.114 | I6: =F6/E6 -> 0.035694735 | J6: 0.487 | K6: 0.28 | L6: =J6/(1+(1-K6)*I6) -> 0.4747976 | M6: =G6/H6 -> 0.0084184195 | N6: =L6/(1-M6) -> 0.47882858
B7: Lupin | C7: 455.67891 | D7: 2117.05 | E7: =C7*D7/1000 -> 964.69503 | F7: 29.217 | G7: 18.3021 | H7: 966.44 | I7: =F7/E7 -> 0.030286255 | J7: 0.492 | K7: 0.28 | L7: =J7/(1+(1-K7)*I7) -> 0.48150035 | M7: =G7/H7 -> 0.018937647 | N7: =L7/(1-M7) -> 0.49079485
B8: Aurobindo Pharma | C8: 585.93861 | D8: 1522.5 | E8: =C8*D8/1000 -> 892.09153 | F8: 66.476 | G8: 63.288 | H8: 904.558 | I8: =F8/E8 -> 0.074517017 | J8: 0.83 | K8: 0.28 | L8: =J8/(1+(1-K8)*I8) -> 0.78773618 | M8: =G8/H8 -> 0.069965663 | N8: =L8/(1-M8) -> 0.84699688
B9: Average | I9: =AVERAGE(I3:I8) -> 0.028141943 | J9: =AVERAGE(J3:J8) -> 0.49916667 | M9: =AVERAGE(M3:M8) -> 0.03498861 | N9: =AVERAGE(N3:N8) -> 0.50623722
B10: Sunpharma | C10: 2399.335 | D10: 1668.75 | E10: =C10*D10/1000 -> 4003.8902 | F10: 32.7367 | G10: 191.052 | H10: 4136.591 | I10: =F10/E10 -> 0.0081762232 | J10: 0.74 | K10: 0.28 | M10: =+G10/H10 -> 0.046185857
B11: Sunpharma Fundamental Beta | C11: =N9*(1+(1-K10)*I10) -> 0.50921738

Sheet India 10-Year Bond Yield Histor
A1: Date | B1: Yield Rate (%) | C1: (1+ytm)
A2: 45505 | B2: 6.973 | C2: =1+(B2/100) -> 1.06973
A3: 45474 | B3: 6.924 | C3: =1+(B3/100) -> 1.06924 | E3: Risk Free Rate Historical | F3: =GEOMEAN(C2:C319)-1 -> 0.078118207
A4: 45444 | B4: 7.008 | C4: =1+(B4/100) -> 1.07008
A5: 45413 | B5: 6.986 | C5: =1+(B5/100) -> 1.06986
A6: 45383 | B6: 7.195 | C6: =1+(B6/100) -> 1.07195
A7: 45352 | B7: 7.052 | C7: =1+(B7/100) -> 1.07052
A8: 45323 | B8: 7.078 | C8: =1+(B8/100) -> 1.07078
A9: 45292 | B9: 7.144 | C9: =1+(B9/100) -> 1.07144
A10: 45261 | B10: 7.176 | C10: =1+(B10/100) -> 1.07176
A11: 45231 | B11: 7.279 | C11: =1+(B11/100) -> 1.07279
A12: 45200 | B12: 7.351 | C12: =1+(B12/100) -> 1.07351
A13: 45170 | B13: 7.21 | C13: =1+(B13/100) -> 1.0721
A14: 45139 | B14: 7.166 | C14: =1+(B14/100) -> 1.07166
A15: 45108 | B15: 7.172 | C15: =1+(B15/100) -> 1.07172
... A319: 35855 | B319: 12.086 | C319: =1+(B319/100) -> 1.12086

Sheet WACC
C3: Cost Of Equity
C5: Risk Free Rate (Forward) | D5: 0.071
C6: NIFTY 50 | D6: Year 2024 | E6: 24010.6
C7: NIFTY 50 | D7: Year 2000 | E7: 1471.45
C8: Market Risk Premium | D8: =(E6/E7)^(1/24)-1 -> 0.12338183
C9: Fundamental Beta | D9: ='Fundamental Beta'!C11 -> 0.50921738
C10: Historical Risk Free Rate | D10: ='India 10-Year Bond Yield Histor'!F3 -> 0.078118207
C11: Cost of Equity | D11: =D5+(D9*(D8-D10)) -> 0.094049025
C13: Cost of Debt
C15: Rating as per CRISIL | D15: AAA Stable
C16: Default Spread basis point as per rating | D16: 0
C17: Risk Free Rate | D17: =D5 -> 0.071
C18: Cost of Debt | D18: =D17+(D16/100) -> 0.071
C19: Tax Rate | D19: 0.28
C20: After Tax Cost of Debt | D20: =D18*(1-D19) -> 0.05112
C22: WACC
C24: Equity (Market Cap) | D24: ='Relative Valuation'!F6 -> 4003.8902
C25: Total Debt | D25: ='Fundamental Beta'!F10 -> 32.7367
C26: Debt / (Debt +Equity) | D26: =D25/($D$25+$D$24) -> 0.0081099147
C27: Equity / (Debt+Equity) | D27: =D24/($D$25+$D$24) -> 0.99189009
C28: WACC | D28: =(D26*D20)+(D27*D11) -> 0.093700874

Sheet Relative Valuation
D2: Relative Valuation
B5: Sr No. | C5: Company | D5: Share Price (INR) | E5: No. Of Outstanding Shares (In Millions) | F5: Market Cap (In Billions) | G5: EV (Current In Billions)) | H5: Revenue TTM (In Billions) | I5: Revenue Growth (5 Year CAGR) | J5: Revenue (1 Yr Forward) | K5: Revenue (Expected Growth Rate) | L5: EBITDA TTM (In Billions) | M5: EBITDA (5-Year CAGR) | N5: Forward EPS (Adjusted) | O5: EPS (Expected Growth Rate)
B6: 1 | C6: Sunpharma | D6: 1668.75 | E6: 2399.335 | F6: =E6*D6/1000 -> 4003.8902 | G6: 4097.843 | H6: 484.9781 | I6: =(477.584/323.2517)^0.2-1 -> 0.081189427 | J6: 531.2212 | K6: =J6/477.5845-1 -> 0.11230829 | L6: 132.6489 | M6: =(132.5254/69.5828)^0.2-1 -> 0.13752106 | N6: 46.53 | O6: =N6/41.8-1 -> 0.11315789
B7: 2 | C7: Cipla | D7: 1577.45 | E7: 807.36706 | F7: =E7*D7/1000 -> 1273.5812 | G7: 1228.453 | H7: 258.0211 | I7: =(254.4663/166.9485)^0.2-1 -> 0.087951539 | J7: 278.5549 | K7: =(278.5549/254.4663)-1 -> 0.094663223 | L7: 65.1294 | M7: =(64.0046/32.8528)^0.2-1 -> 0.14268824 | N7: 58.01 | O7: =(58.01/50.86)-1 -> 0.14058199
B8: 3 | C8: Zydus Lifescience | D8: 1206.7 | E8: 1006.234 | F8: =E8*D8/1000 -> 1214.2226 | G8: 1231.7617 | H8: 200.152 | I8: =(190.215/138.121)^0.2-1 -> 0.066097708 | J8: 225.7554 | K8: =(J8/190.215)-1 -> 0.18684331 | L8: 57.957 | M8: =(52.889/27.981)^0.2-1 -> 0.13579624 | N8: 44.74 | O8: =N8/36.86-1 -> 0.21378188
B9: 4 | C9: Dr. Reddy Laboratories | D9: 6933.85 | E9: =166.818466-0.289791 -> 166.52867 | F9: =E9*D9/1000 -> 1154.6849 | G9: 1120.8984 | H9: 288.507 | I9: =(277.051/174.6)^0.2-1 -> 0.096738518 | J9: 309.3639 | K9: =(J9/279.164)-1 -> 0.10817978 | L9: 82.738 | M9: =(79.334/44.371)^0.2-1 -> 0.12323862 | N9: 346.49 | O9: =N9/317.03-1 -> 0.09292496
B10: 5 | C10: Torrent Pharmaceuticals | D10: 3343.65 | E10: 338.44544 | F10: =E10*D10/1000 -> 1131.6431 | G10: 1167.3124 | H10: 108.29 | I10: =(105.6231/77.8001)^0.2-1 -> 0.06305504 | J10: 120.0687 | K10: =(J10/105.6231)-1 -> 0.13676554 | L10: 34.81 | M10: =(33.4968/21.7036)^0.2-1 -> 0.090672363 | N10: 60.13 | O10: =N10/46.37-1 -> 0.29674358
B11: 6 | C11: Lupin | D11: 2117.05 | E11: 455.67891 | F11: =E11*D11/1000 -> 964.69503 | G11: 976.518 | H11: 204.2856 | I11: =(196.5634/151.428)^0.2-1 -> 0.053560049 | J11: 220.086 | K11: =(J11/196.5634)-1 -> 0.11966928 | L11: 42.2822 | M11: =(37.7435/25.4465)^0.2-1 -> 0.082038772 | N11: 59.48 | O11: =N11/41.66-1 -> 0.42774844
B12: 7 | C12: Aurobindo Pharma | D12: 1522.5 | E12: 585.93861 | F12: =E12*D12/1000 -> 892.09153 | G12: 897.4684 | H12: 294.4022 | I12: =(287.045/227.379)^0.2-1 -> 0.047707196 | J12: 316.0188 | K12: =(J12/287.045)-1 -> 0.10093818 | L12: 62.814 | M12: =(59.053/49.0135)^0.2-1 -> 0.037971072 | N12: 67.49 | O12: =N12/54.62-1 -> 0.23562798
B13: 8 | C13: Glenmark Pharmaceuticals | D13: 1668.75 | E13: 282.19 | F13: =E13*D13/1000 -> 470.90456 | G13: 464.0539 | H13: 118.8283 | I13: =(115.7174/103.9723)^0.2-1 -> 0.021636036 | J13: 137.8703 | K13: =(J13/115.7174)-1 -> 0.19143966 | L13: 13.4619 | M13: =(12.4424/16.9926)^0.2-1 -> -0.060430598 | N13: 50.62 | O13: =(N13-(-64.88))/64.88 -> 1.7802096
B16: Sr No. | C16: Valuation Multiple / growth | D16: EV / Revenuem(TTM) | E16: EV/ Revenue(Forward) | F16: EV/EBITDA (TTM) | G16: P/EPS (Forwarded) | I16: Multiples of Sunpharma
B17: 1 | C17: Cipla | D17: =(G7/H7)/(I7*100) -> 0.54132724 | E17: =(G7/J7)/(K7*100) -> 0.46587184 | F17: =(G7/L7)/(M7*100) -> 1.3218838 | G17: =(D7/N7)/(O7*100) -> 1.9342965 | I17: EV / Revenuem(TTM) | J17: =(G6/H6)/(I6*100) -> 1.0407195
B18: 2 | C18: Zydus Lifescience | D18: =(G8/H8)/(I8*100) -> 0.93106578 | E18: =(G8/J8)/(K8*100) -> 0.29201893 | F18: =(G8/L8)/(M8*100) -> 1.5650675 | G18: =(D8/N8)/(O8*100) -> 1.2616313 | I18: EV/ Revenue(Forward) | J18: =(G6/J6)/(K6*100) -> 0.68685979
B19: 3 | C19: Dr. Reddy Laboratories | D19: =(G9/H9)/(I9*100) -> 0.4016155 | E19: =(G9/J9)/(K9*100) -> 0.33492728 | F19: =(G9/L9)/(M9*100) -> 1.0992954 | G19: =(D9/N9)/(O9*100) -> 2.1535321 | I19: EV/EBITDA (TTM) | J19: =(G6/L6)/(M6*100) -> 2.2463761
B20: 4 | C20: Torrent Pharmaceuticals | D20: =(G10/H10)/(I10*100) -> 1.7095387 | E20: =(G10/J10)/(K10*100) -> 0.71085433 | F20: =(G10/L10)/(M10*100) -> 3.6983511 | G20: =(D10/N10)/(O10*100) -> 1.873908 | I20: P/EPS (Forwarded) | J20: =(D6/N6)/(O6*100) -> 3.1693731
B21: 5 | C21: Lupin | D21: =(G11/H11)/(I11*100) -> 0.89248625 | E21: =(G11/J11)/(K11*100) -> 0.3707705 | F21: =(G11/L11)/(M11*100) -> 2.8151629 | G21: =(D11/N11)/(O11*100) -> 0.83209272
B22: 6 | C22: Aurobindo Pharma | D22: =(G12/H12)/(I12*100) -> 0.63899024 | E22: =(G12/J12)/(K12*100) -> 0.2813525 | F22: =(G12/L12)/(M12*100) -> 3.762789 | G22: =(D12/N12)/(O12*100) -> 0.95739471
C24: Mean | D24: =AVERAGE(D17:D22) -> 0.85250395 | E24: =AVERAGE(E17:E22) -> 0.40929923 | F24: =AVERAGE(F17:F22) -> 2.3770916 | G24: =AVERAGE(G17:G22) -> 1.5021426
C25: Median | D25: =MEDIAN(D17:D22) -> 0.76573824 | E25: =MEDIAN(E17:E22) -> 0.35284889 | F25: =MEDIAN(F17:F22) -> 2.1901152 | G25: =MEDIAN(G17:G22) -> 1.5677696
C26: 1st Quartile | D26: =_xlfn.QUARTILE.INC(D17:D22,1) -> 0.56574299 | E26: =_xlfn.QUARTILE.INC(E17:E22,1) -> 0.30274601 | F26: =_xlfn.QUARTILE.INC(F17:F22,1) -> 1.3826797 | G26: =_xlfn.QUARTILE.INC(G17:G22,1) -> 1.0334538
C27: 3rd Quatrile | D27: =_xlfn.QUARTILE.INC(D17:D22,3) -> 0.9214209 | E27: =_xlfn.QUARTILE.INC(E17:E22,3) -> 0.4420965 | F27: =_xlfn.QUARTILE.INC(F17:F22,3) -> 3.4775541 | G27: =_xlfn.QUARTILE.INC(G17:G22,3) -> 1.9191994
C29: Implied Enterprise Value of Sunpharma | D29: EV / Revenuem(TTM) | E29: EV/ Revenue(Forward) | F29: EV/EBITDA (TTM)
C30: Mean | D30: =D24*$H$6*($I$6*100) -> 3356.7423 | E30: =E24*$J$6*($K$6*100) -> 2441.9016 | F30: =F24*$L$6*($M$6*100) -> 4336.2945
C31: Median | D31: =D25*$H$6*($I$6*100) -> 3015.1015 | E31: =E25*$J$6*($K$6*100) -> 2105.1157 | F31: =F25*$L$6*($M$6*100) -> 3995.2118
C32: 1st Quartile | D32: =D26*$H$6*($I$6*100) -> 2227.6183 | E32: =E26*$J$6*($K$6*100) -> 1806.1993 | F32: =F26*$L$6*($M$6*100) -> 2522.2867
C33: 3rd Quatrile | D33: =D27*$H$6*($I$6*100) -> 3628.1035 | E33: =E27*$J$6*($K$6*100) -> 2637.5719 | F33: =F27*$L$6*($M$6*100) -> 6343.76
C35: Sunpharma | D35: INR In Billions
C36: Cash & Equivalents | D36: 191.052
C37: Preferred Equity | D37: 0
C38: Minority Interest | D38: 34.3922
C39: Total Debt | D39: 32.7367
C41: Implied Shareprice of Sunpharma | D41: EV / Revenuem(TTM) | E41: EV/ Revenue(Forward) | F41: EV/EBITDA (TTM) | G41: P/EPS (Forwarded)
C42: Mean | D42: =(D30-SUM($D$36:$D$39))*1000/$E$6 -> 1291.4251 | E42: =(E30-SUM($D$36:$D$39))*1000/$E$6 -> 910.1358 | F42: =(F30-SUM($D$36:$D$39))*1000/$E$6 -> 1699.685 | G42: =G24*$N$6*($O$6*100) -> 790.91364
C43: Median | D43: =(D31-SUM($D$36:$D$39))*1000/$E$6 -> 1149.0353 | E43: =(E31-SUM($D$36:$D$39))*1000/$E$6 -> 769.76948 | F43: =(F31-SUM($D$36:$D$39))*1000/$E$6 -> 1557.5278 | G43: =G25*$N$6*($O$6*100) -> 825.46785
C44: 1st Quartile | D44: =(D32-SUM($D$36:$D$39))*1000/$E$6 -> 820.82638 | E44: =(E32-SUM($D$36:$D$39))*1000/$E$6 -> 645.18643 | F44: =(F32-SUM($D$36:$D$39))*1000/$E$6 -> 943.63887 | G44: =G26*$N$6*($O$6*100) -> 544.13793
C45: 3rd Quatrile | D45: =(D33-SUM($D$36:$D$39))*1000/$E$6 -> 1404.5236 | E45: =(E33-SUM($D$36:$D$39))*1000/$E$6 -> 991.6877 | F45: =(F33-SUM($D$36:$D$39))*1000/$E$6 -> 2536.3608 | G45: =G27*$N$6*($O$6*100) -> 1010.5039
C48: For Pharma EV/EBITDA & P/EPS are important Ratios
C50: Current Share Price | D50: =D6 -> 1668.75
C51: Implied Share Price | D51: =F45 -> 2536.3608
C52: Undervalued (EV/EBITDA long term) | D52: =(D51-D6)/D6 -> 0.51991656
...
